<?xml version="1.0"?>
<robot xmlns:xacro="http://www.ros.org/wiki/xacro">

    <xacro:include filename="inertial_macros.xacro" />

    <material name="white">
        <color rgba="1 1 1 1" />
    </material>

    <material name="orange">
        <color rgba="1 0.3 0.1 1" />
    </material>

    <material name="blue">
        <color rgba="0.2 0.2 1 1" />
    </material>

    <material name="black">
        <color rgba="0 0 0 1" />
    </material>


    <!-- BASE LINK -->

    <link name="base_link"></link>


    <!-- CHASSIS LINK -->

    <joint name="chassis_joint" type="fixed">
        <parent link="base_link" />
        <child link="chassis" />
        <origin xyz="-0.1 0 0" />
    </joint>

    <link name="chassis">
        <visual>
            <origin xyz="0.15 0 0.075" />
            <geometry>
                <box size="0.3 0.3 0.15" />
            </geometry>
            <material name="blue" />
        </visual>
        <collision>
            <origin xyz="0.15 0 0.075" />
            <geometry>
                <box size="0.3 0.3 0.15" />
            </geometry>
        </collision>
        <xacro:inertial_box mass="0.5" x="0.3" y="0.3" z="0.15">
            <origin xyz="0.15 0 0.075" rpy="0 0 0" />
        </xacro:inertial_box>
    </link>

    <gazebo reference="chassis">
        <material>Gazebo/White</material>
    </gazebo>

    <!-- LEFT WHEEL LINK -->

    <joint name="left_wheel_joint" type="continuous">
        <parent link="base_link" />
        <child link="left_wheel" />
        <origin xyz="0 0.175 0" rpy="-${pi/2} 0 0" /> <!--CHANGING TO CHECK RVIZ2-->
        <axis xyz="0 0 1" />
    </joint>

    <link name="left_wheel">
        <visual>
            <geometry>
                <cylinder radius="0.05" length="0.04" />
            </geometry>
            <material name="blue" />
        </visual>
        <collision>
            <geometry>
                <cylinder radius="0.05" length="0.04" />
            </geometry>
        </collision>
        <xacro:inertial_cylinder mass="0.1" length="0.04" radius="0.05">
            <origin xyz="0 0 0" rpy="0 0 0" />
        </xacro:inertial_cylinder>
    </link>

    <gazebo reference="left_wheel">
        <material>Gazebo/Blue</material>
    </gazebo>


    <!-- RIGHT WHEEL LINK -->

    <joint name="right_wheel_joint" type="continuous">
        <parent link="base_link" />
        <child link="right_wheel" />
        <origin xyz="0 -0.175 0" rpy="${pi/2} 0 0" />
        <axis xyz="0 0 -1" />
    </joint>

    <link name="right_wheel">
        <visual>
            <geometry>
                <cylinder radius="0.05" length="0.04" />
            </geometry>
            <material name="blue" />
        </visual>
        <collision>
            <geometry>
                <cylinder radius="0.05" length="0.04" />
            </geometry>
        </collision>
        <xacro:inertial_cylinder mass="0.1" length="0.04" radius="0.05">
            <origin xyz="0 0 0" rpy="0 0 0" />
        </xacro:inertial_cylinder>
    </link>

    <gazebo reference="right_wheel">
        <material>Gazebo/Blue</material>
    </gazebo>


    <!-- CASTER WHEEL LINK -->

    <joint name="caster_wheel_joint" type="fixed">
        <parent link="chassis" />
        <child link="caster_wheel" />
        <origin xyz="0.24 0 0" />
    </joint>


    <link name="caster_wheel">
        <visual>
            <geometry>
                <sphere radius="0.05" />
            </geometry>
            <material name="black" />
        </visual>
        <collision>
            <geometry>
                <sphere radius="0.05" />
            </geometry>
        </collision>
        <xacro:inertial_sphere mass="0.8" radius="0.05">
            <origin xyz="0 0 0" rpy="0 0 0" />
        </xacro:inertial_sphere>
    </link>

    <gazebo reference="caster_wheel">
        <material>Gazebo/Black</material>
        <mu1 value="0.001" />
        <mu2 value="0.001" />
    </gazebo>

    <!-- LIDAR LINK -->


    <link name="lidar_link">
        <!-- <inertial>
            <origin xyz="0 0 0" rpy="0 0 0" />
            <mass value="0.125" />
            <inertia ixx="0.001" ixy="0" ixz="0" iyy="0.001" iyz="0" izz="0.001" />
        </inertial> -->

        <xacro:inertial_cylinder mass="0.125" length="0.055" radius="0.508">
            <origin xyz="0 0 0" rpy="0 0 0" />
        </xacro:inertial_cylinder>

        <collision>
            <origin xyz="0 0 0" rpy="0 0 0" />
            <geometry>
                <cylinder radius="0.0508" length="0.055" />
            </geometry>
        </collision>

        <visual>
            <origin xyz="0 0 0" rpy="0 0 0" />
            <geometry>
                <cylinder radius="0.0508" length="0.055" />
            </geometry>
        </visual>
    </link>

    <joint name="lidar_joint" type="fixed">
        <parent link="base_link" />
        <child link="lidar_link" />
        <origin xyz="0 0 0.175" rpy="0 0 0" />
    </joint>

    <gazebo reference="lidar_link">
        <sensor name="lidar" type="ray">
            <always_on>true</always_on>
            <visualize>true</visualize>
            <update_rate>5</update_rate>
            <ray>
                <scan>
                    <horizontal>
                        <samples>360</samples>
                        <resolution>1.000000</resolution>
                        <min_angle>0.000000</min_angle>
                        <max_angle>6.280000</max_angle>
                    </horizontal>
                </scan>
                <range>
                    <min>0.120000</min>
                    <max>3.5</max>
                    <resolution>0.015000</resolution>
                </range>
                <noise>
                    <type>gaussian</type>
                    <mean>0.0</mean>
                    <stddev>0.01</stddev>
                </noise>
            </ray>
            <plugin name="scan" filename="libgazebo_ros_ray_sensor.so">
                <ros>
                    <remapping>~/out:=scan</remapping>
                </ros>
                <output_type>sensor_msgs/LaserScan</output_type>
                <frame_name>lidar_link</frame_name>
            </plugin>
        </sensor>
        <material>Gazebo/Orange</material>
    </gazebo>

    <!-- GRIPPER AXIS LINK -->

    <joint name="gripper_axis_joint" type="fixed">
        <parent link="base_link" />
        <child link="gripper_axis_link" />
        <origin xyz="0.225 0 0.02" rpy="0 0 0" />
    </joint>

    <link name="gripper_axis_link">
        <visual>
            <geometry>
                <box size="0.05 0.3 0.05" />
                <origin xyz="0 0 0" rpy="0 0 0" />
            </geometry>
            <material name="blue" />
        </visual>
        <collision>
            <geometry>
                <box size="0.1 0.2 0.1" />
            </geometry>
        </collision>
        <xacro:inertial_box mass="0.1" x="0.1" y="0.2" z="0.1">
            <origin xyz="0 0 0" rpy="0 0 0" />
        </xacro:inertial_box>
    </link>

    <gazebo reference="gripper_axis_link">
        <material>Gazebo/Blue</material>
    </gazebo>

    <!-- GRIPPER RIGHT LINK -->

    <joint name="gripper_right_joint" type="prismatic">
        <parent link="base_link" />
        <child link="gripper_right_link" />
        <limit effort="1000.0" lower="0" upper="0.08" velocity="0.5" />
        <origin xyz="0.27 -0.1 0.02" rpy="0 0 1.57" />
    </joint>

    <link name="gripper_right_link">
        <visual>
            <geometry>
                <box size="0.02 0.15 0.02" />
                <origin xyz="0 -0.05 0" rpy="0 0 0" />
            </geometry>
            <material name="blue" />
        </visual>
        <collision>
            <geometry>
                <box size="0.02 0.15 0.02" />
            </geometry>
        </collision>
        <xacro:inertial_box mass="0.1" x="0.02" y="0.15" z="0.02">
            <origin xyz="0 0 0" rpy="0 0 0" />
        </xacro:inertial_box>
    </link>

    <gazebo reference="gripper_right_link">
        <material>Gazebo/white</material>
    </gazebo>

    <!-- GRIPPER LEFT LINK -->

    <joint name="gripper_left_joint" type="prismatic">
        <parent link="base_link" />
        <child link="gripper_left_link" />
        <limit effort="1000.0" lower="-0.08" upper="0" velocity="0.5" />
        <origin xyz="0.27 0.1 0.02" rpy="0 0 1.57" />
    </joint>

    <link name="gripper_left_link">
        <visual>
            <geometry>
                <box size="0.02 0.15 0.02" />
                <origin xyz="0 0.05 0" rpy="0 0 0" />
            </geometry>
            <material name="blue" />
        </visual>
        <collision>
            <geometry>
                <box size="0.02 0.15 0.02" />
                <origin xyz="0 0 0" rpy="0 0 0" />
            </geometry>
        </collision>
        <xacro:inertial_box mass="0.1" x="0.02" y="0.15" z="0.02">
            <origin xyz="0 0 0" rpy="0 0 0" />
        </xacro:inertial_box>
    </link>

    <gazebo reference="gripper_left_link">
        <material>Gazebo/white</material>
    </gazebo>

<!-- GAZEBO ROS2 CONTROL -->

    <ros2_control name="GazeboSystem" type="system">
        <hardware>
          <plugin>gazebo_ros2_control/GazeboSystem</plugin>
        </hardware>
        <joint name="gripper_right_joint">
            <command_interface name="position">
              <param name="min">-1</param>
              <param name="max">1</param>
            </command_interface>
            <state_interface name="position">
            <state_interface name="velocity"/>
            <state_interface name="effort"/>
            </state_interface>
          </joint>
        <joint name="gripper_left_joint">
            <command_interface name="position">
              <param name="min">-1</param>
              <param name="max">1</param>
            </command_interface>
            <state_interface name="position">
            <state_interface name="velocity"/>
            <state_interface name="effort"/>
            </state_interface>
          </joint>
      </ros2_control>

</robot>